frontend/slides/case_studies4.txt
{:format :pointed-dict, :data [{#uuid "ff0051ea-2479-4922-b67e-04ab2bbea9c3" {:updated-at 1726717935090, :entity-type :font, :events [], :type "custom", :keyspace [:workspace #uuid "115577da-7857-4831-9fc4-c520aa2009cb"], :id #uuid "ff0051ea-2479-4922-b67e-04ab2bbea9c3", :styles [{:name "300 Italic", :style "italic", :weight 300, :sources [{:url "https://pitch-assets-ccb95893-de3f-4266-973c-20049231b248.s3.eu-west-1.amazonaws.com/fonts/09adb1f6-a700-4ba7-a69a-fbd373b5f0d3.woff", :format "woff"}]} {:name "300", :style "normal", :weight 300, :sources [{:url "https://pitch-assets-ccb95893-de3f-4266-973c-20049231b248.s3.eu-west-1.amazonaws.com/fonts/e8e7a9a8-4740-4ec6-903a-f76e1547888f.woff", :format "woff"}]} {:name "400 Italic", :style "italic", :weight 400, :sources [{:url "https://pitch-assets-ccb95893-de3f-4266-973c-20049231b248.s3.eu-west-1.amazonaws.com/fonts/71bb8a9f-857a-4094-aba7-67880347413c.woff", :format "woff"}]} {:name "400", :style "normal", :weight 400, :sources [{:url "https://pitch-assets-ccb95893-de3f-4266-973c-20049231b248.s3.eu-west-1.amazonaws.com/fonts/2c948cd8-7a1b-4faa-a5a4-e13eec656717.woff", :format "woff"}]} {:name "500", :style "normal", :weight 500, :sources [{:url "https://pitch-assets-ccb95893-de3f-4266-973c-20049231b248.s3.eu-west-1.amazonaws.com/fonts/c8ef3205-959f-4387-bdd1-b01c7343b583.woff", :format "woff"}]} {:name "550", :style "italic", :weight 500, :sources [{:url "https://pitch-assets-ccb95893-de3f-4266-973c-20049231b248.s3.eu-west-1.amazonaws.com/fonts/e9860aba-c865-4748-8fc0-79cf980868eb.woff", :format "woff"}]} {:name "600", :style "normal", :weight 600, :sources [{:url "https://pitch-assets-ccb95893-de3f-4266-973c-20049231b248.s3.eu-west-1.amazonaws.com/fonts/dae0dbb5-3984-4f40-a3c1-e778f41085e5.woff", :format "woff"}]} {:name "600 (IT)", :style "italic", :weight 600, :sources [{:url "https://pitch-assets-ccb95893-de3f-4266-973c-20049231b248.s3.eu-west-1.amazonaws.com/fonts/b83dc5a6-75de-4850-aad3-a56960d7dad8.woff", :format "woff"}]} {:name "700", :style "normal", :weight 700, :sources [{:url "https://pitch-assets-ccb95893-de3f-4266-973c-20049231b248.s3.eu-west-1.amazonaws.com/fonts/d6e6ff8b-3b98-4a7d-8d2e-bf7e121be581.woff", :format "woff"}]}], :created-at 1726717935090, :font-family "TWK Lausanne"}, #uuid "6d4cf1a7-6291-4bbd-ae52-9f27249832e5" {:fill-color {:r 255, :g 255, :b 255, :a 0.16}, :entity-type :block, :shape-type :rectangle, :white-space :break-spaces, :coords {:y-start 0.3014086023569541, :x-start 0.03648290374240781, :x-end 0.0985669168995641, :y-end 0.3328900838384356}, :events [], :border? true, :even-padding? true, :variation :rectangle-outline-radius, :border-width 1, :id #uuid "6d4cf1a7-6291-4bbd-ae52-9f27249832e5", :block-type :shape, :border-color {:r 255, :g 255, :b 255, :a 0.19}, :corner-roundness 0.25, :body "<p></p>", :arrowhead-type :triangle}, #uuid "36ecfe41-2773-4e24-b018-0aaa1c4a5711" {:line-height 1.1, :entity-type :block, :text-align :left, :white-space :break-spaces, :font-size 0.65, :font-weight 500, :auto-resize? false, :auto-align-default :left, :coords {:y-start 0.3508277243249225, :x-start 0.521690410672918, :x-end 0.7044233424457859, :y-end 0.40378554521725646}, :events [], :text-color {:r 255, :g 255, :b 255, :a 1}, :auto-vertical-align-default :top, :text-align-vertical :top, :text-type :headline-medium, :used-fonts #{#uuid "ff00e4cf-60ba-4f16-951a-72c5311ef140"}, :id #uuid "36ecfe41-2773-4e24-b018-0aaa1c4a5711", :block-type :text, :body "<p>PE-Backed Global Staffing Group</p>"}, #uuid "be741765-6e13-4ac6-92be-a04934739d66" {:line-height 1.25, :entity-type :block, :text-align :left, :white-space :break-spaces, :font-size 0.425, :font-weight 400, :auto-resize? false, :auto-align-default :left, :coords {:y-start 0.8155164259204081, :x-start 0.27370477870752896, :x-end 0.4845771745408623, :y-end 0.9138960555500377}, :events [], :text-color {:r 147, :g 157, :b 168, :a 1}, :auto-vertical-align-default :top, :text-align-vertical :top, :text-type :headline-medium, :opacity 0.6, :id #uuid "be741765-6e13-4ac6-92be-a04934739d66", :block-type :text, :letter-spacing -0.02, :body "<p>AI re-engineered patient ops, procurement, and finance. Voice agents automated scheduling, ML optimized stock, and copilots digitized billing - lifting throughput, freeing staff time, and accelerating cash conversion.</p>"}, #uuid "eb53bff9-7ec5-4e72-adb9-1771573377f4" {:entity-type :block, :shape-type :rectangle, :white-space :break-spaces, :coords {:y-start 0.26682979051718914, :x-start 0.5052197823860644, :x-end 0.7365508746571309, :y-end 0.6861801287963951}, :fill-gradient {:start {:r 0, :g 0, :b 0, :a 0.84}, :stop {:r 0, :g 0, :b 0, :a 0}, :angle 90}, :events [], :even-padding? true, :opacity 1, :id #uuid "eb53bff9-7ec5-4e72-adb9-1771573377f4", :block-type :shape, :corner-roundness 0, :body "<p></p>", :corner-roundness-px 10, :arrowhead-type :triangle}, #uuid "c5bbb026-5099-42d4-80b2-5a17c80bde8d" {:fill-color {:r 229, :g 231, :b 240, :a 1}, :entity-type :block, :shape-type :rectangle, :coords {:x-start 0.02129391832473064, :x-end 0.9787011058247308, :y-start 0.17619231250995154, :y-end 0.17804416436180343}, :events [], :border? true, :even-padding? true, :border-width 0, :id #uuid "c5bbb026-5099-42d4-80b2-5a17c80bde8d", :block-type :shape, :border-color {:r 229, :g 231, :b 240, :a 1}, :arrowhead-type :triangle}, #uuid "4291d1f4-587d-4b7c-ad2a-4b53baf71d70" {:entity-type :block, :coords {:y-start 0.2670987037037037, :x-start 0.26320796792878565, :x-end 0.49445796792878566, :y-end 0.6861414226656999}, :events [], :original-aspect-ratio? true, :overlay-opacity 0.12, :filter {:sepia nil, :grayscale 20, :contrast 117, :brightness 105, :saturate 95, :hue-rotate -5}, :used-fonts #{#uuid "ff00e4cf-60ba-4f16-951a-72c5311ef140"}, :blur 0, :image-aspect-ratio 1.4998720900486058, :id #uuid "4291d1f4-587d-4b7c-ad2a-4b53baf71d70", :image-position {:x 30.592395165102275, :y 50}, :url "https://images.unsplash.com/photo-1728342057908-7f6c4a3262f8?crop=entropy&cs=tinysrgb&fit=max&fm=jpg&ixid=M3wyMTIyMnwwfDF8c2VhcmNofDY1fHxkZW50YWwlMjBjbGluaWMlMjBieSUyMHVnb2xrb3Z8ZW58MHx8fHwxNzUxMDY3OTgzfDA&ixlib=rb-4.1.0&q=80&w=1080", :block-type :image, :image-scale-x 1.7464726814304712, :corner-roundness 0, :locked-aspect-ratio? false, :overlay-color {:r 0, :g 0, :b 0, :a 1}, :created-at 1751067987269, :corner-roundness-px 10}, #uuid "435ef314-cea3-43a2-903a-fe0ed14089dd" {:entity-type :block, :white-space :break-spaces, :font-size 0.6, :font-weight 400, :auto-resize? false, :auto-align-default :left, :coords {:y-start 0.03505724460145338, :x-start 0.041088058179856016, :x-end 0.9368779675426491, :y-end 0.06839057793478671}, :events [], :text-color {:r 147, :g 157, :b 168, :a 1}, :auto-vertical-align-default :top, :text-type :paragraph, :used-fonts #{#uuid "ff0051ea-2479-4922-b67e-04ab2bbea9c3"}, :id #uuid "435ef314-cea3-43a2-903a-fe0ed14089dd", :block-type :text, :body "<p>Selected Case Studies — Strategic Transformation Programs</p>", :font-family "font-ff0051ea-2479-4922-b67e-04ab2bbea9c3"}, #uuid "a208e305-84ad-476a-b861-0f4d2caed06f" {:entity-type :block, :shape-type :rectangle, :white-space :break-spaces, :coords {:y-start 0.2670987037037037, :x-start 0.26343175872011426, :x-end 0.4947628509911808, :y-end 0.6864490419829097}, :fill-gradient {:start {:r 0, :g 0, :b 0, :a 0.84}, :stop {:r 0, :g 0, :b 0, :a 0}, :angle 90}, :events [], :even-padding? true, :opacity 1, :id #uuid "a208e305-84ad-476a-b861-0f4d2caed06f", :block-type :shape, :corner-roundness 0, :body "<p></p>", :corner-roundness-px 10, :arrowhead-type :triangle}, #uuid "30d3881b-17a0-45af-9b0d-8b5c9964648c" {:fill-color {:r 255, :g 255, :b 255, :a 0.16}, :entity-type :block, :shape-type :rectangle, :white-space :break-spaces, :coords {:y-start 0, :x-start 0, :x-end 0.05186930991288363, :y-end 0.031481481481481444}, :events [], :border? true, :even-padding? true, :variation :rectangle-outline-radius, :border-width 1, :id #uuid "30d3881b-17a0-45af-9b0d-8b5c99646
